{
 "cells": [
  {
   "cell_type": "markdown",
   "id": "d82dca94",
   "metadata": {},
   "source": [
    "## Project Scenario\n",
    "Netflix! What started in 1997 as a DVD rental service has now grown into one of the most prominent entertainment and media companies in the world.\n",
    "\n",
    "With its vast collection of movies and TV shows, Netflix presents an ideal opportunity to sharpen your exploratory data analysis skills and explore the entertainment landscape.\n",
    "\n",
    "You work for a creative agency specializing in nostalgic content. Your task is to research movies released in the 1990s. You’ll dive into Netflix's extensive data, perform exploratory data analysis, and uncover trends that defined this iconic decade of filmmaking.\n",
    "\n",
    "You’ve been provided with the dataset netflix_data.csv, along with a detailed table explaining the column names and descriptions. Feel free to experiment further once you've submitted your analysis!"
   ]
  },
  {
   "cell_type": "markdown",
   "id": "98853940",
   "metadata": {},
   "source": [
    "## Code Implementation"
   ]
  },
  {
   "cell_type": "code",
   "execution_count": null,
   "id": "0ac7223b",
   "metadata": {},
   "outputs": [
    {
     "name": "stderr",
     "output_type": "stream",
     "text": [
      "\n",
      "A module that was compiled using NumPy 1.x cannot be run in\n",
      "NumPy 2.2.4 as it may crash. To support both 1.x and 2.x\n",
      "versions of NumPy, modules must be compiled with NumPy 2.0.\n",
      "Some module may need to rebuild instead e.g. with 'pybind11>=2.12'.\n",
      "\n",
      "If you are a user of the module, the easiest solution will be to\n",
      "downgrade to 'numpy<2' or try to upgrade the affected module.\n",
      "We expect that some modules will need time to support NumPy 2.\n",
      "\n",
      "Traceback (most recent call last):  File \"<frozen runpy>\", line 198, in _run_module_as_main\n",
      "  File \"<frozen runpy>\", line 88, in _run_code\n",
      "  File \"c:\\Users\\Dell\\anaconda3\\Lib\\site-packages\\ipykernel_launcher.py\", line 17, in <module>\n",
      "    app.launch_new_instance()\n",
      "  File \"C:\\Users\\Dell\\AppData\\Roaming\\Python\\Python312\\site-packages\\traitlets\\config\\application.py\", line 1075, in launch_instance\n",
      "    app.start()\n",
      "  File \"c:\\Users\\Dell\\anaconda3\\Lib\\site-packages\\ipykernel\\kernelapp.py\", line 701, in start\n",
      "    self.io_loop.start()\n",
      "  File \"C:\\Users\\Dell\\AppData\\Roaming\\Python\\Python312\\site-packages\\tornado\\platform\\asyncio.py\", line 205, in start\n",
      "    self.asyncio_loop.run_forever()\n",
      "  File \"c:\\Users\\Dell\\anaconda3\\Lib\\asyncio\\windows_events.py\", line 322, in run_forever\n",
      "    super().run_forever()\n",
      "  File \"c:\\Users\\Dell\\anaconda3\\Lib\\asyncio\\base_events.py\", line 641, in run_forever\n",
      "    self._run_once()\n",
      "  File \"c:\\Users\\Dell\\anaconda3\\Lib\\asyncio\\base_events.py\", line 1986, in _run_once\n",
      "    handle._run()\n",
      "  File \"c:\\Users\\Dell\\anaconda3\\Lib\\asyncio\\events.py\", line 88, in _run\n",
      "    self._context.run(self._callback, *self._args)\n",
      "  File \"c:\\Users\\Dell\\anaconda3\\Lib\\site-packages\\ipykernel\\kernelbase.py\", line 534, in dispatch_queue\n",
      "    await self.process_one()\n",
      "  File \"c:\\Users\\Dell\\anaconda3\\Lib\\site-packages\\ipykernel\\kernelbase.py\", line 523, in process_one\n",
      "    await dispatch(*args)\n",
      "  File \"c:\\Users\\Dell\\anaconda3\\Lib\\site-packages\\ipykernel\\kernelbase.py\", line 429, in dispatch_shell\n",
      "    await result\n",
      "  File \"c:\\Users\\Dell\\anaconda3\\Lib\\site-packages\\ipykernel\\kernelbase.py\", line 767, in execute_request\n",
      "    reply_content = await reply_content\n",
      "  File \"c:\\Users\\Dell\\anaconda3\\Lib\\site-packages\\ipykernel\\ipkernel.py\", line 429, in do_execute\n",
      "    res = shell.run_cell(\n",
      "  File \"c:\\Users\\Dell\\anaconda3\\Lib\\site-packages\\ipykernel\\zmqshell.py\", line 549, in run_cell\n",
      "    return super().run_cell(*args, **kwargs)\n",
      "  File \"C:\\Users\\Dell\\AppData\\Roaming\\Python\\Python312\\site-packages\\IPython\\core\\interactiveshell.py\", line 3077, in run_cell\n",
      "    result = self._run_cell(\n",
      "  File \"C:\\Users\\Dell\\AppData\\Roaming\\Python\\Python312\\site-packages\\IPython\\core\\interactiveshell.py\", line 3132, in _run_cell\n",
      "    result = runner(coro)\n",
      "  File \"C:\\Users\\Dell\\AppData\\Roaming\\Python\\Python312\\site-packages\\IPython\\core\\async_helpers.py\", line 128, in _pseudo_sync_runner\n",
      "    coro.send(None)\n",
      "  File \"C:\\Users\\Dell\\AppData\\Roaming\\Python\\Python312\\site-packages\\IPython\\core\\interactiveshell.py\", line 3336, in run_cell_async\n",
      "    has_raised = await self.run_ast_nodes(code_ast.body, cell_name,\n",
      "  File \"C:\\Users\\Dell\\AppData\\Roaming\\Python\\Python312\\site-packages\\IPython\\core\\interactiveshell.py\", line 3519, in run_ast_nodes\n",
      "    if await self.run_code(code, result, async_=asy):\n",
      "  File \"C:\\Users\\Dell\\AppData\\Roaming\\Python\\Python312\\site-packages\\IPython\\core\\interactiveshell.py\", line 3579, in run_code\n",
      "    exec(code_obj, self.user_global_ns, self.user_ns)\n",
      "  File \"C:\\Users\\Dell\\AppData\\Local\\Temp\\ipykernel_21572\\2264814713.py\", line 2, in <module>\n",
      "    import pandas as pd\n",
      "  File \"C:\\Users\\Dell\\AppData\\Roaming\\Python\\Python312\\site-packages\\pandas\\__init__.py\", line 39, in <module>\n",
      "    from pandas.compat import (\n",
      "  File \"C:\\Users\\Dell\\AppData\\Roaming\\Python\\Python312\\site-packages\\pandas\\compat\\__init__.py\", line 27, in <module>\n",
      "    from pandas.compat.pyarrow import (\n",
      "  File \"C:\\Users\\Dell\\AppData\\Roaming\\Python\\Python312\\site-packages\\pandas\\compat\\pyarrow.py\", line 8, in <module>\n",
      "    import pyarrow as pa\n",
      "  File \"c:\\Users\\Dell\\anaconda3\\Lib\\site-packages\\pyarrow\\__init__.py\", line 65, in <module>\n",
      "    import pyarrow.lib as _lib\n"
     ]
    },
    {
     "ename": "ImportError",
     "evalue": "\nA module that was compiled using NumPy 1.x cannot be run in\nNumPy 2.2.4 as it may crash. To support both 1.x and 2.x\nversions of NumPy, modules must be compiled with NumPy 2.0.\nSome module may need to rebuild instead e.g. with 'pybind11>=2.12'.\n\nIf you are a user of the module, the easiest solution will be to\ndowngrade to 'numpy<2' or try to upgrade the affected module.\nWe expect that some modules will need time to support NumPy 2.\n\n",
     "output_type": "error",
     "traceback": [
      "\u001b[1;31m---------------------------------------------------------------------------\u001b[0m",
      "\u001b[1;31mImportError\u001b[0m                               Traceback (most recent call last)",
      "File \u001b[1;32m~\\AppData\\Roaming\\Python\\Python312\\site-packages\\numpy\\core\\_multiarray_umath.py:44\u001b[0m, in \u001b[0;36m__getattr__\u001b[1;34m(attr_name)\u001b[0m\n\u001b[0;32m     39\u001b[0m     \u001b[38;5;66;03m# Also print the message (with traceback).  This is because old versions\u001b[39;00m\n\u001b[0;32m     40\u001b[0m     \u001b[38;5;66;03m# of NumPy unfortunately set up the import to replace (and hide) the\u001b[39;00m\n\u001b[0;32m     41\u001b[0m     \u001b[38;5;66;03m# error.  The traceback shouldn't be needed, but e.g. pytest plugins\u001b[39;00m\n\u001b[0;32m     42\u001b[0m     \u001b[38;5;66;03m# seem to swallow it and we should be failing anyway...\u001b[39;00m\n\u001b[0;32m     43\u001b[0m     sys\u001b[38;5;241m.\u001b[39mstderr\u001b[38;5;241m.\u001b[39mwrite(msg \u001b[38;5;241m+\u001b[39m tb_msg)\n\u001b[1;32m---> 44\u001b[0m     \u001b[38;5;28;01mraise\u001b[39;00m \u001b[38;5;167;01mImportError\u001b[39;00m(msg)\n\u001b[0;32m     46\u001b[0m ret \u001b[38;5;241m=\u001b[39m \u001b[38;5;28mgetattr\u001b[39m(_multiarray_umath, attr_name, \u001b[38;5;28;01mNone\u001b[39;00m)\n\u001b[0;32m     47\u001b[0m \u001b[38;5;28;01mif\u001b[39;00m ret \u001b[38;5;129;01mis\u001b[39;00m \u001b[38;5;28;01mNone\u001b[39;00m:\n",
      "\u001b[1;31mImportError\u001b[0m: \nA module that was compiled using NumPy 1.x cannot be run in\nNumPy 2.2.4 as it may crash. To support both 1.x and 2.x\nversions of NumPy, modules must be compiled with NumPy 2.0.\nSome module may need to rebuild instead e.g. with 'pybind11>=2.12'.\n\nIf you are a user of the module, the easiest solution will be to\ndowngrade to 'numpy<2' or try to upgrade the affected module.\nWe expect that some modules will need time to support NumPy 2.\n\n"
     ]
    },
    {
     "name": "stderr",
     "output_type": "stream",
     "text": [
      "\n",
      "A module that was compiled using NumPy 1.x cannot be run in\n",
      "NumPy 2.2.4 as it may crash. To support both 1.x and 2.x\n",
      "versions of NumPy, modules must be compiled with NumPy 2.0.\n",
      "Some module may need to rebuild instead e.g. with 'pybind11>=2.12'.\n",
      "\n",
      "If you are a user of the module, the easiest solution will be to\n",
      "downgrade to 'numpy<2' or try to upgrade the affected module.\n",
      "We expect that some modules will need time to support NumPy 2.\n",
      "\n",
      "Traceback (most recent call last):  File \"<frozen runpy>\", line 198, in _run_module_as_main\n",
      "  File \"<frozen runpy>\", line 88, in _run_code\n",
      "  File \"c:\\Users\\Dell\\anaconda3\\Lib\\site-packages\\ipykernel_launcher.py\", line 17, in <module>\n",
      "    app.launch_new_instance()\n",
      "  File \"C:\\Users\\Dell\\AppData\\Roaming\\Python\\Python312\\site-packages\\traitlets\\config\\application.py\", line 1075, in launch_instance\n",
      "    app.start()\n",
      "  File \"c:\\Users\\Dell\\anaconda3\\Lib\\site-packages\\ipykernel\\kernelapp.py\", line 701, in start\n",
      "    self.io_loop.start()\n",
      "  File \"C:\\Users\\Dell\\AppData\\Roaming\\Python\\Python312\\site-packages\\tornado\\platform\\asyncio.py\", line 205, in start\n",
      "    self.asyncio_loop.run_forever()\n",
      "  File \"c:\\Users\\Dell\\anaconda3\\Lib\\asyncio\\windows_events.py\", line 322, in run_forever\n",
      "    super().run_forever()\n",
      "  File \"c:\\Users\\Dell\\anaconda3\\Lib\\asyncio\\base_events.py\", line 641, in run_forever\n",
      "    self._run_once()\n",
      "  File \"c:\\Users\\Dell\\anaconda3\\Lib\\asyncio\\base_events.py\", line 1986, in _run_once\n",
      "    handle._run()\n",
      "  File \"c:\\Users\\Dell\\anaconda3\\Lib\\asyncio\\events.py\", line 88, in _run\n",
      "    self._context.run(self._callback, *self._args)\n",
      "  File \"c:\\Users\\Dell\\anaconda3\\Lib\\site-packages\\ipykernel\\kernelbase.py\", line 534, in dispatch_queue\n",
      "    await self.process_one()\n",
      "  File \"c:\\Users\\Dell\\anaconda3\\Lib\\site-packages\\ipykernel\\kernelbase.py\", line 523, in process_one\n",
      "    await dispatch(*args)\n",
      "  File \"c:\\Users\\Dell\\anaconda3\\Lib\\site-packages\\ipykernel\\kernelbase.py\", line 429, in dispatch_shell\n",
      "    await result\n",
      "  File \"c:\\Users\\Dell\\anaconda3\\Lib\\site-packages\\ipykernel\\kernelbase.py\", line 767, in execute_request\n",
      "    reply_content = await reply_content\n",
      "  File \"c:\\Users\\Dell\\anaconda3\\Lib\\site-packages\\ipykernel\\ipkernel.py\", line 429, in do_execute\n",
      "    res = shell.run_cell(\n",
      "  File \"c:\\Users\\Dell\\anaconda3\\Lib\\site-packages\\ipykernel\\zmqshell.py\", line 549, in run_cell\n",
      "    return super().run_cell(*args, **kwargs)\n",
      "  File \"C:\\Users\\Dell\\AppData\\Roaming\\Python\\Python312\\site-packages\\IPython\\core\\interactiveshell.py\", line 3077, in run_cell\n",
      "    result = self._run_cell(\n",
      "  File \"C:\\Users\\Dell\\AppData\\Roaming\\Python\\Python312\\site-packages\\IPython\\core\\interactiveshell.py\", line 3132, in _run_cell\n",
      "    result = runner(coro)\n",
      "  File \"C:\\Users\\Dell\\AppData\\Roaming\\Python\\Python312\\site-packages\\IPython\\core\\async_helpers.py\", line 128, in _pseudo_sync_runner\n",
      "    coro.send(None)\n",
      "  File \"C:\\Users\\Dell\\AppData\\Roaming\\Python\\Python312\\site-packages\\IPython\\core\\interactiveshell.py\", line 3336, in run_cell_async\n",
      "    has_raised = await self.run_ast_nodes(code_ast.body, cell_name,\n",
      "  File \"C:\\Users\\Dell\\AppData\\Roaming\\Python\\Python312\\site-packages\\IPython\\core\\interactiveshell.py\", line 3519, in run_ast_nodes\n",
      "    if await self.run_code(code, result, async_=asy):\n",
      "  File \"C:\\Users\\Dell\\AppData\\Roaming\\Python\\Python312\\site-packages\\IPython\\core\\interactiveshell.py\", line 3579, in run_code\n",
      "    exec(code_obj, self.user_global_ns, self.user_ns)\n",
      "  File \"C:\\Users\\Dell\\AppData\\Local\\Temp\\ipykernel_21572\\2264814713.py\", line 2, in <module>\n",
      "    import pandas as pd\n",
      "  File \"C:\\Users\\Dell\\AppData\\Roaming\\Python\\Python312\\site-packages\\pandas\\__init__.py\", line 62, in <module>\n",
      "    from pandas.core.api import (\n",
      "  File \"C:\\Users\\Dell\\AppData\\Roaming\\Python\\Python312\\site-packages\\pandas\\core\\api.py\", line 9, in <module>\n",
      "    from pandas.core.dtypes.dtypes import (\n",
      "  File \"C:\\Users\\Dell\\AppData\\Roaming\\Python\\Python312\\site-packages\\pandas\\core\\dtypes\\dtypes.py\", line 24, in <module>\n",
      "    from pandas._libs import (\n",
      "  File \"c:\\Users\\Dell\\anaconda3\\Lib\\site-packages\\pyarrow\\__init__.py\", line 65, in <module>\n",
      "    import pyarrow.lib as _lib\n"
     ]
    },
    {
     "ename": "ImportError",
     "evalue": "\nA module that was compiled using NumPy 1.x cannot be run in\nNumPy 2.2.4 as it may crash. To support both 1.x and 2.x\nversions of NumPy, modules must be compiled with NumPy 2.0.\nSome module may need to rebuild instead e.g. with 'pybind11>=2.12'.\n\nIf you are a user of the module, the easiest solution will be to\ndowngrade to 'numpy<2' or try to upgrade the affected module.\nWe expect that some modules will need time to support NumPy 2.\n\n",
     "output_type": "error",
     "traceback": [
      "\u001b[1;31m---------------------------------------------------------------------------\u001b[0m",
      "\u001b[1;31mImportError\u001b[0m                               Traceback (most recent call last)",
      "File \u001b[1;32m~\\AppData\\Roaming\\Python\\Python312\\site-packages\\numpy\\core\\_multiarray_umath.py:44\u001b[0m, in \u001b[0;36m__getattr__\u001b[1;34m(attr_name)\u001b[0m\n\u001b[0;32m     39\u001b[0m     \u001b[38;5;66;03m# Also print the message (with traceback).  This is because old versions\u001b[39;00m\n\u001b[0;32m     40\u001b[0m     \u001b[38;5;66;03m# of NumPy unfortunately set up the import to replace (and hide) the\u001b[39;00m\n\u001b[0;32m     41\u001b[0m     \u001b[38;5;66;03m# error.  The traceback shouldn't be needed, but e.g. pytest plugins\u001b[39;00m\n\u001b[0;32m     42\u001b[0m     \u001b[38;5;66;03m# seem to swallow it and we should be failing anyway...\u001b[39;00m\n\u001b[0;32m     43\u001b[0m     sys\u001b[38;5;241m.\u001b[39mstderr\u001b[38;5;241m.\u001b[39mwrite(msg \u001b[38;5;241m+\u001b[39m tb_msg)\n\u001b[1;32m---> 44\u001b[0m     \u001b[38;5;28;01mraise\u001b[39;00m \u001b[38;5;167;01mImportError\u001b[39;00m(msg)\n\u001b[0;32m     46\u001b[0m ret \u001b[38;5;241m=\u001b[39m \u001b[38;5;28mgetattr\u001b[39m(_multiarray_umath, attr_name, \u001b[38;5;28;01mNone\u001b[39;00m)\n\u001b[0;32m     47\u001b[0m \u001b[38;5;28;01mif\u001b[39;00m ret \u001b[38;5;129;01mis\u001b[39;00m \u001b[38;5;28;01mNone\u001b[39;00m:\n",
      "\u001b[1;31mImportError\u001b[0m: \nA module that was compiled using NumPy 1.x cannot be run in\nNumPy 2.2.4 as it may crash. To support both 1.x and 2.x\nversions of NumPy, modules must be compiled with NumPy 2.0.\nSome module may need to rebuild instead e.g. with 'pybind11>=2.12'.\n\nIf you are a user of the module, the easiest solution will be to\ndowngrade to 'numpy<2' or try to upgrade the affected module.\nWe expect that some modules will need time to support NumPy 2.\n\n"
     ]
    },
    {
     "name": "stderr",
     "output_type": "stream",
     "text": [
      "\n",
      "A module that was compiled using NumPy 1.x cannot be run in\n",
      "NumPy 2.2.4 as it may crash. To support both 1.x and 2.x\n",
      "versions of NumPy, modules must be compiled with NumPy 2.0.\n",
      "Some module may need to rebuild instead e.g. with 'pybind11>=2.12'.\n",
      "\n",
      "If you are a user of the module, the easiest solution will be to\n",
      "downgrade to 'numpy<2' or try to upgrade the affected module.\n",
      "We expect that some modules will need time to support NumPy 2.\n",
      "\n",
      "Traceback (most recent call last):  File \"<frozen runpy>\", line 198, in _run_module_as_main\n",
      "  File \"<frozen runpy>\", line 88, in _run_code\n",
      "  File \"c:\\Users\\Dell\\anaconda3\\Lib\\site-packages\\ipykernel_launcher.py\", line 17, in <module>\n",
      "    app.launch_new_instance()\n",
      "  File \"C:\\Users\\Dell\\AppData\\Roaming\\Python\\Python312\\site-packages\\traitlets\\config\\application.py\", line 1075, in launch_instance\n",
      "    app.start()\n",
      "  File \"c:\\Users\\Dell\\anaconda3\\Lib\\site-packages\\ipykernel\\kernelapp.py\", line 701, in start\n",
      "    self.io_loop.start()\n",
      "  File \"C:\\Users\\Dell\\AppData\\Roaming\\Python\\Python312\\site-packages\\tornado\\platform\\asyncio.py\", line 205, in start\n",
      "    self.asyncio_loop.run_forever()\n",
      "  File \"c:\\Users\\Dell\\anaconda3\\Lib\\asyncio\\windows_events.py\", line 322, in run_forever\n",
      "    super().run_forever()\n",
      "  File \"c:\\Users\\Dell\\anaconda3\\Lib\\asyncio\\base_events.py\", line 641, in run_forever\n",
      "    self._run_once()\n",
      "  File \"c:\\Users\\Dell\\anaconda3\\Lib\\asyncio\\base_events.py\", line 1986, in _run_once\n",
      "    handle._run()\n",
      "  File \"c:\\Users\\Dell\\anaconda3\\Lib\\asyncio\\events.py\", line 88, in _run\n",
      "    self._context.run(self._callback, *self._args)\n",
      "  File \"c:\\Users\\Dell\\anaconda3\\Lib\\site-packages\\ipykernel\\kernelbase.py\", line 534, in dispatch_queue\n",
      "    await self.process_one()\n",
      "  File \"c:\\Users\\Dell\\anaconda3\\Lib\\site-packages\\ipykernel\\kernelbase.py\", line 523, in process_one\n",
      "    await dispatch(*args)\n",
      "  File \"c:\\Users\\Dell\\anaconda3\\Lib\\site-packages\\ipykernel\\kernelbase.py\", line 429, in dispatch_shell\n",
      "    await result\n",
      "  File \"c:\\Users\\Dell\\anaconda3\\Lib\\site-packages\\ipykernel\\kernelbase.py\", line 767, in execute_request\n",
      "    reply_content = await reply_content\n",
      "  File \"c:\\Users\\Dell\\anaconda3\\Lib\\site-packages\\ipykernel\\ipkernel.py\", line 429, in do_execute\n",
      "    res = shell.run_cell(\n",
      "  File \"c:\\Users\\Dell\\anaconda3\\Lib\\site-packages\\ipykernel\\zmqshell.py\", line 549, in run_cell\n",
      "    return super().run_cell(*args, **kwargs)\n",
      "  File \"C:\\Users\\Dell\\AppData\\Roaming\\Python\\Python312\\site-packages\\IPython\\core\\interactiveshell.py\", line 3077, in run_cell\n",
      "    result = self._run_cell(\n",
      "  File \"C:\\Users\\Dell\\AppData\\Roaming\\Python\\Python312\\site-packages\\IPython\\core\\interactiveshell.py\", line 3132, in _run_cell\n",
      "    result = runner(coro)\n",
      "  File \"C:\\Users\\Dell\\AppData\\Roaming\\Python\\Python312\\site-packages\\IPython\\core\\async_helpers.py\", line 128, in _pseudo_sync_runner\n",
      "    coro.send(None)\n",
      "  File \"C:\\Users\\Dell\\AppData\\Roaming\\Python\\Python312\\site-packages\\IPython\\core\\interactiveshell.py\", line 3336, in run_cell_async\n",
      "    has_raised = await self.run_ast_nodes(code_ast.body, cell_name,\n",
      "  File \"C:\\Users\\Dell\\AppData\\Roaming\\Python\\Python312\\site-packages\\IPython\\core\\interactiveshell.py\", line 3519, in run_ast_nodes\n",
      "    if await self.run_code(code, result, async_=asy):\n",
      "  File \"C:\\Users\\Dell\\AppData\\Roaming\\Python\\Python312\\site-packages\\IPython\\core\\interactiveshell.py\", line 3579, in run_code\n",
      "    exec(code_obj, self.user_global_ns, self.user_ns)\n",
      "  File \"C:\\Users\\Dell\\AppData\\Local\\Temp\\ipykernel_21572\\2264814713.py\", line 2, in <module>\n",
      "    import pandas as pd\n",
      "  File \"C:\\Users\\Dell\\AppData\\Roaming\\Python\\Python312\\site-packages\\pandas\\__init__.py\", line 62, in <module>\n",
      "    from pandas.core.api import (\n",
      "  File \"C:\\Users\\Dell\\AppData\\Roaming\\Python\\Python312\\site-packages\\pandas\\core\\api.py\", line 28, in <module>\n",
      "    from pandas.core.arrays import Categorical\n",
      "  File \"C:\\Users\\Dell\\AppData\\Roaming\\Python\\Python312\\site-packages\\pandas\\core\\arrays\\__init__.py\", line 1, in <module>\n",
      "    from pandas.core.arrays.arrow import ArrowExtensionArray\n",
      "  File \"C:\\Users\\Dell\\AppData\\Roaming\\Python\\Python312\\site-packages\\pandas\\core\\arrays\\arrow\\__init__.py\", line 5, in <module>\n",
      "    from pandas.core.arrays.arrow.array import ArrowExtensionArray\n",
      "  File \"C:\\Users\\Dell\\AppData\\Roaming\\Python\\Python312\\site-packages\\pandas\\core\\arrays\\arrow\\array.py\", line 50, in <module>\n",
      "    from pandas.core import (\n",
      "  File \"C:\\Users\\Dell\\AppData\\Roaming\\Python\\Python312\\site-packages\\pandas\\core\\ops\\__init__.py\", line 8, in <module>\n",
      "    from pandas.core.ops.array_ops import (\n",
      "  File \"C:\\Users\\Dell\\AppData\\Roaming\\Python\\Python312\\site-packages\\pandas\\core\\ops\\array_ops.py\", line 56, in <module>\n",
      "    from pandas.core.computation import expressions\n",
      "  File \"C:\\Users\\Dell\\AppData\\Roaming\\Python\\Python312\\site-packages\\pandas\\core\\computation\\expressions.py\", line 21, in <module>\n",
      "    from pandas.core.computation.check import NUMEXPR_INSTALLED\n",
      "  File \"C:\\Users\\Dell\\AppData\\Roaming\\Python\\Python312\\site-packages\\pandas\\core\\computation\\check.py\", line 5, in <module>\n",
      "    ne = import_optional_dependency(\"numexpr\", errors=\"warn\")\n",
      "  File \"C:\\Users\\Dell\\AppData\\Roaming\\Python\\Python312\\site-packages\\pandas\\compat\\_optional.py\", line 135, in import_optional_dependency\n",
      "    module = importlib.import_module(name)\n",
      "  File \"c:\\Users\\Dell\\anaconda3\\Lib\\importlib\\__init__.py\", line 90, in import_module\n",
      "    return _bootstrap._gcd_import(name[level:], package, level)\n",
      "  File \"c:\\Users\\Dell\\anaconda3\\Lib\\site-packages\\numexpr\\__init__.py\", line 24, in <module>\n",
      "    from numexpr.interpreter import MAX_THREADS, use_vml, __BLOCK_SIZE1__\n"
     ]
    },
    {
     "ename": "AttributeError",
     "evalue": "_ARRAY_API not found",
     "output_type": "error",
     "traceback": [
      "\u001b[1;31m---------------------------------------------------------------------------\u001b[0m",
      "\u001b[1;31mAttributeError\u001b[0m                            Traceback (most recent call last)",
      "\u001b[1;31mAttributeError\u001b[0m: _ARRAY_API not found"
     ]
    },
    {
     "name": "stderr",
     "output_type": "stream",
     "text": [
      "\n",
      "A module that was compiled using NumPy 1.x cannot be run in\n",
      "NumPy 2.2.4 as it may crash. To support both 1.x and 2.x\n",
      "versions of NumPy, modules must be compiled with NumPy 2.0.\n",
      "Some module may need to rebuild instead e.g. with 'pybind11>=2.12'.\n",
      "\n",
      "If you are a user of the module, the easiest solution will be to\n",
      "downgrade to 'numpy<2' or try to upgrade the affected module.\n",
      "We expect that some modules will need time to support NumPy 2.\n",
      "\n",
      "Traceback (most recent call last):  File \"<frozen runpy>\", line 198, in _run_module_as_main\n",
      "  File \"<frozen runpy>\", line 88, in _run_code\n",
      "  File \"c:\\Users\\Dell\\anaconda3\\Lib\\site-packages\\ipykernel_launcher.py\", line 17, in <module>\n",
      "    app.launch_new_instance()\n",
      "  File \"C:\\Users\\Dell\\AppData\\Roaming\\Python\\Python312\\site-packages\\traitlets\\config\\application.py\", line 1075, in launch_instance\n",
      "    app.start()\n",
      "  File \"c:\\Users\\Dell\\anaconda3\\Lib\\site-packages\\ipykernel\\kernelapp.py\", line 701, in start\n",
      "    self.io_loop.start()\n",
      "  File \"C:\\Users\\Dell\\AppData\\Roaming\\Python\\Python312\\site-packages\\tornado\\platform\\asyncio.py\", line 205, in start\n",
      "    self.asyncio_loop.run_forever()\n",
      "  File \"c:\\Users\\Dell\\anaconda3\\Lib\\asyncio\\windows_events.py\", line 322, in run_forever\n",
      "    super().run_forever()\n",
      "  File \"c:\\Users\\Dell\\anaconda3\\Lib\\asyncio\\base_events.py\", line 641, in run_forever\n",
      "    self._run_once()\n",
      "  File \"c:\\Users\\Dell\\anaconda3\\Lib\\asyncio\\base_events.py\", line 1986, in _run_once\n",
      "    handle._run()\n",
      "  File \"c:\\Users\\Dell\\anaconda3\\Lib\\asyncio\\events.py\", line 88, in _run\n",
      "    self._context.run(self._callback, *self._args)\n",
      "  File \"c:\\Users\\Dell\\anaconda3\\Lib\\site-packages\\ipykernel\\kernelbase.py\", line 534, in dispatch_queue\n",
      "    await self.process_one()\n",
      "  File \"c:\\Users\\Dell\\anaconda3\\Lib\\site-packages\\ipykernel\\kernelbase.py\", line 523, in process_one\n",
      "    await dispatch(*args)\n",
      "  File \"c:\\Users\\Dell\\anaconda3\\Lib\\site-packages\\ipykernel\\kernelbase.py\", line 429, in dispatch_shell\n",
      "    await result\n",
      "  File \"c:\\Users\\Dell\\anaconda3\\Lib\\site-packages\\ipykernel\\kernelbase.py\", line 767, in execute_request\n",
      "    reply_content = await reply_content\n",
      "  File \"c:\\Users\\Dell\\anaconda3\\Lib\\site-packages\\ipykernel\\ipkernel.py\", line 429, in do_execute\n",
      "    res = shell.run_cell(\n",
      "  File \"c:\\Users\\Dell\\anaconda3\\Lib\\site-packages\\ipykernel\\zmqshell.py\", line 549, in run_cell\n",
      "    return super().run_cell(*args, **kwargs)\n",
      "  File \"C:\\Users\\Dell\\AppData\\Roaming\\Python\\Python312\\site-packages\\IPython\\core\\interactiveshell.py\", line 3077, in run_cell\n",
      "    result = self._run_cell(\n",
      "  File \"C:\\Users\\Dell\\AppData\\Roaming\\Python\\Python312\\site-packages\\IPython\\core\\interactiveshell.py\", line 3132, in _run_cell\n",
      "    result = runner(coro)\n",
      "  File \"C:\\Users\\Dell\\AppData\\Roaming\\Python\\Python312\\site-packages\\IPython\\core\\async_helpers.py\", line 128, in _pseudo_sync_runner\n",
      "    coro.send(None)\n",
      "  File \"C:\\Users\\Dell\\AppData\\Roaming\\Python\\Python312\\site-packages\\IPython\\core\\interactiveshell.py\", line 3336, in run_cell_async\n",
      "    has_raised = await self.run_ast_nodes(code_ast.body, cell_name,\n",
      "  File \"C:\\Users\\Dell\\AppData\\Roaming\\Python\\Python312\\site-packages\\IPython\\core\\interactiveshell.py\", line 3519, in run_ast_nodes\n",
      "    if await self.run_code(code, result, async_=asy):\n",
      "  File \"C:\\Users\\Dell\\AppData\\Roaming\\Python\\Python312\\site-packages\\IPython\\core\\interactiveshell.py\", line 3579, in run_code\n",
      "    exec(code_obj, self.user_global_ns, self.user_ns)\n",
      "  File \"C:\\Users\\Dell\\AppData\\Local\\Temp\\ipykernel_21572\\2264814713.py\", line 2, in <module>\n",
      "    import pandas as pd\n",
      "  File \"C:\\Users\\Dell\\AppData\\Roaming\\Python\\Python312\\site-packages\\pandas\\__init__.py\", line 62, in <module>\n",
      "    from pandas.core.api import (\n",
      "  File \"C:\\Users\\Dell\\AppData\\Roaming\\Python\\Python312\\site-packages\\pandas\\core\\api.py\", line 28, in <module>\n",
      "    from pandas.core.arrays import Categorical\n",
      "  File \"C:\\Users\\Dell\\AppData\\Roaming\\Python\\Python312\\site-packages\\pandas\\core\\arrays\\__init__.py\", line 1, in <module>\n",
      "    from pandas.core.arrays.arrow import ArrowExtensionArray\n",
      "  File \"C:\\Users\\Dell\\AppData\\Roaming\\Python\\Python312\\site-packages\\pandas\\core\\arrays\\arrow\\__init__.py\", line 5, in <module>\n",
      "    from pandas.core.arrays.arrow.array import ArrowExtensionArray\n",
      "  File \"C:\\Users\\Dell\\AppData\\Roaming\\Python\\Python312\\site-packages\\pandas\\core\\arrays\\arrow\\array.py\", line 64, in <module>\n",
      "    from pandas.core.arrays.masked import BaseMaskedArray\n",
      "  File \"C:\\Users\\Dell\\AppData\\Roaming\\Python\\Python312\\site-packages\\pandas\\core\\arrays\\masked.py\", line 60, in <module>\n",
      "    from pandas.core import (\n",
      "  File \"C:\\Users\\Dell\\AppData\\Roaming\\Python\\Python312\\site-packages\\pandas\\core\\nanops.py\", line 52, in <module>\n",
      "    bn = import_optional_dependency(\"bottleneck\", errors=\"warn\")\n",
      "  File \"C:\\Users\\Dell\\AppData\\Roaming\\Python\\Python312\\site-packages\\pandas\\compat\\_optional.py\", line 135, in import_optional_dependency\n",
      "    module = importlib.import_module(name)\n",
      "  File \"c:\\Users\\Dell\\anaconda3\\Lib\\importlib\\__init__.py\", line 90, in import_module\n",
      "    return _bootstrap._gcd_import(name[level:], package, level)\n",
      "  File \"c:\\Users\\Dell\\anaconda3\\Lib\\site-packages\\bottleneck\\__init__.py\", line 7, in <module>\n",
      "    from .move import (move_argmax, move_argmin, move_max, move_mean, move_median,\n"
     ]
    },
    {
     "ename": "ImportError",
     "evalue": "\nA module that was compiled using NumPy 1.x cannot be run in\nNumPy 2.2.4 as it may crash. To support both 1.x and 2.x\nversions of NumPy, modules must be compiled with NumPy 2.0.\nSome module may need to rebuild instead e.g. with 'pybind11>=2.12'.\n\nIf you are a user of the module, the easiest solution will be to\ndowngrade to 'numpy<2' or try to upgrade the affected module.\nWe expect that some modules will need time to support NumPy 2.\n\n",
     "output_type": "error",
     "traceback": [
      "\u001b[1;31m---------------------------------------------------------------------------\u001b[0m",
      "\u001b[1;31mImportError\u001b[0m                               Traceback (most recent call last)",
      "File \u001b[1;32m~\\AppData\\Roaming\\Python\\Python312\\site-packages\\numpy\\core\\_multiarray_umath.py:44\u001b[0m, in \u001b[0;36m__getattr__\u001b[1;34m(attr_name)\u001b[0m\n\u001b[0;32m     39\u001b[0m     \u001b[38;5;66;03m# Also print the message (with traceback).  This is because old versions\u001b[39;00m\n\u001b[0;32m     40\u001b[0m     \u001b[38;5;66;03m# of NumPy unfortunately set up the import to replace (and hide) the\u001b[39;00m\n\u001b[0;32m     41\u001b[0m     \u001b[38;5;66;03m# error.  The traceback shouldn't be needed, but e.g. pytest plugins\u001b[39;00m\n\u001b[0;32m     42\u001b[0m     \u001b[38;5;66;03m# seem to swallow it and we should be failing anyway...\u001b[39;00m\n\u001b[0;32m     43\u001b[0m     sys\u001b[38;5;241m.\u001b[39mstderr\u001b[38;5;241m.\u001b[39mwrite(msg \u001b[38;5;241m+\u001b[39m tb_msg)\n\u001b[1;32m---> 44\u001b[0m     \u001b[38;5;28;01mraise\u001b[39;00m \u001b[38;5;167;01mImportError\u001b[39;00m(msg)\n\u001b[0;32m     46\u001b[0m ret \u001b[38;5;241m=\u001b[39m \u001b[38;5;28mgetattr\u001b[39m(_multiarray_umath, attr_name, \u001b[38;5;28;01mNone\u001b[39;00m)\n\u001b[0;32m     47\u001b[0m \u001b[38;5;28;01mif\u001b[39;00m ret \u001b[38;5;129;01mis\u001b[39;00m \u001b[38;5;28;01mNone\u001b[39;00m:\n",
      "\u001b[1;31mImportError\u001b[0m: \nA module that was compiled using NumPy 1.x cannot be run in\nNumPy 2.2.4 as it may crash. To support both 1.x and 2.x\nversions of NumPy, modules must be compiled with NumPy 2.0.\nSome module may need to rebuild instead e.g. with 'pybind11>=2.12'.\n\nIf you are a user of the module, the easiest solution will be to\ndowngrade to 'numpy<2' or try to upgrade the affected module.\nWe expect that some modules will need time to support NumPy 2.\n\n"
     ]
    },
    {
     "name": "stderr",
     "output_type": "stream",
     "text": [
      "\n",
      "A module that was compiled using NumPy 1.x cannot be run in\n",
      "NumPy 2.2.4 as it may crash. To support both 1.x and 2.x\n",
      "versions of NumPy, modules must be compiled with NumPy 2.0.\n",
      "Some module may need to rebuild instead e.g. with 'pybind11>=2.12'.\n",
      "\n",
      "If you are a user of the module, the easiest solution will be to\n",
      "downgrade to 'numpy<2' or try to upgrade the affected module.\n",
      "We expect that some modules will need time to support NumPy 2.\n",
      "\n",
      "Traceback (most recent call last):  File \"<frozen runpy>\", line 198, in _run_module_as_main\n",
      "  File \"<frozen runpy>\", line 88, in _run_code\n",
      "  File \"c:\\Users\\Dell\\anaconda3\\Lib\\site-packages\\ipykernel_launcher.py\", line 17, in <module>\n",
      "    app.launch_new_instance()\n",
      "  File \"C:\\Users\\Dell\\AppData\\Roaming\\Python\\Python312\\site-packages\\traitlets\\config\\application.py\", line 1075, in launch_instance\n",
      "    app.start()\n",
      "  File \"c:\\Users\\Dell\\anaconda3\\Lib\\site-packages\\ipykernel\\kernelapp.py\", line 701, in start\n",
      "    self.io_loop.start()\n",
      "  File \"C:\\Users\\Dell\\AppData\\Roaming\\Python\\Python312\\site-packages\\tornado\\platform\\asyncio.py\", line 205, in start\n",
      "    self.asyncio_loop.run_forever()\n",
      "  File \"c:\\Users\\Dell\\anaconda3\\Lib\\asyncio\\windows_events.py\", line 322, in run_forever\n",
      "    super().run_forever()\n",
      "  File \"c:\\Users\\Dell\\anaconda3\\Lib\\asyncio\\base_events.py\", line 641, in run_forever\n",
      "    self._run_once()\n",
      "  File \"c:\\Users\\Dell\\anaconda3\\Lib\\asyncio\\base_events.py\", line 1986, in _run_once\n",
      "    handle._run()\n",
      "  File \"c:\\Users\\Dell\\anaconda3\\Lib\\asyncio\\events.py\", line 88, in _run\n",
      "    self._context.run(self._callback, *self._args)\n",
      "  File \"c:\\Users\\Dell\\anaconda3\\Lib\\site-packages\\ipykernel\\kernelbase.py\", line 534, in dispatch_queue\n",
      "    await self.process_one()\n",
      "  File \"c:\\Users\\Dell\\anaconda3\\Lib\\site-packages\\ipykernel\\kernelbase.py\", line 523, in process_one\n",
      "    await dispatch(*args)\n",
      "  File \"c:\\Users\\Dell\\anaconda3\\Lib\\site-packages\\ipykernel\\kernelbase.py\", line 429, in dispatch_shell\n",
      "    await result\n",
      "  File \"c:\\Users\\Dell\\anaconda3\\Lib\\site-packages\\ipykernel\\kernelbase.py\", line 767, in execute_request\n",
      "    reply_content = await reply_content\n",
      "  File \"c:\\Users\\Dell\\anaconda3\\Lib\\site-packages\\ipykernel\\ipkernel.py\", line 429, in do_execute\n",
      "    res = shell.run_cell(\n",
      "  File \"c:\\Users\\Dell\\anaconda3\\Lib\\site-packages\\ipykernel\\zmqshell.py\", line 549, in run_cell\n",
      "    return super().run_cell(*args, **kwargs)\n",
      "  File \"C:\\Users\\Dell\\AppData\\Roaming\\Python\\Python312\\site-packages\\IPython\\core\\interactiveshell.py\", line 3077, in run_cell\n",
      "    result = self._run_cell(\n",
      "  File \"C:\\Users\\Dell\\AppData\\Roaming\\Python\\Python312\\site-packages\\IPython\\core\\interactiveshell.py\", line 3132, in _run_cell\n",
      "    result = runner(coro)\n",
      "  File \"C:\\Users\\Dell\\AppData\\Roaming\\Python\\Python312\\site-packages\\IPython\\core\\async_helpers.py\", line 128, in _pseudo_sync_runner\n",
      "    coro.send(None)\n",
      "  File \"C:\\Users\\Dell\\AppData\\Roaming\\Python\\Python312\\site-packages\\IPython\\core\\interactiveshell.py\", line 3336, in run_cell_async\n",
      "    has_raised = await self.run_ast_nodes(code_ast.body, cell_name,\n",
      "  File \"C:\\Users\\Dell\\AppData\\Roaming\\Python\\Python312\\site-packages\\IPython\\core\\interactiveshell.py\", line 3519, in run_ast_nodes\n",
      "    if await self.run_code(code, result, async_=asy):\n",
      "  File \"C:\\Users\\Dell\\AppData\\Roaming\\Python\\Python312\\site-packages\\IPython\\core\\interactiveshell.py\", line 3579, in run_code\n",
      "    exec(code_obj, self.user_global_ns, self.user_ns)\n",
      "  File \"C:\\Users\\Dell\\AppData\\Local\\Temp\\ipykernel_21572\\2264814713.py\", line 3, in <module>\n",
      "    import matplotlib.pyplot as plt\n",
      "  File \"c:\\Users\\Dell\\anaconda3\\Lib\\site-packages\\matplotlib\\__init__.py\", line 159, in <module>\n",
      "    from . import _api, _version, cbook, _docstring, rcsetup\n",
      "  File \"c:\\Users\\Dell\\anaconda3\\Lib\\site-packages\\matplotlib\\rcsetup.py\", line 28, in <module>\n",
      "    from matplotlib.colors import Colormap, is_color_like\n",
      "  File \"c:\\Users\\Dell\\anaconda3\\Lib\\site-packages\\matplotlib\\colors.py\", line 57, in <module>\n",
      "    from matplotlib import _api, _cm, cbook, scale\n",
      "  File \"c:\\Users\\Dell\\anaconda3\\Lib\\site-packages\\matplotlib\\scale.py\", line 22, in <module>\n",
      "    from matplotlib.ticker import (\n",
      "  File \"c:\\Users\\Dell\\anaconda3\\Lib\\site-packages\\matplotlib\\ticker.py\", line 144, in <module>\n",
      "    from matplotlib import transforms as mtransforms\n",
      "  File \"c:\\Users\\Dell\\anaconda3\\Lib\\site-packages\\matplotlib\\transforms.py\", line 49, in <module>\n",
      "    from matplotlib._path import (\n"
     ]
    },
    {
     "ename": "ImportError",
     "evalue": "\nA module that was compiled using NumPy 1.x cannot be run in\nNumPy 2.2.4 as it may crash. To support both 1.x and 2.x\nversions of NumPy, modules must be compiled with NumPy 2.0.\nSome module may need to rebuild instead e.g. with 'pybind11>=2.12'.\n\nIf you are a user of the module, the easiest solution will be to\ndowngrade to 'numpy<2' or try to upgrade the affected module.\nWe expect that some modules will need time to support NumPy 2.\n\n",
     "output_type": "error",
     "traceback": [
      "\u001b[1;31m---------------------------------------------------------------------------\u001b[0m",
      "\u001b[1;31mImportError\u001b[0m                               Traceback (most recent call last)",
      "File \u001b[1;32m~\\AppData\\Roaming\\Python\\Python312\\site-packages\\numpy\\core\\_multiarray_umath.py:44\u001b[0m, in \u001b[0;36m__getattr__\u001b[1;34m(attr_name)\u001b[0m\n\u001b[0;32m     39\u001b[0m     \u001b[38;5;66;03m# Also print the message (with traceback).  This is because old versions\u001b[39;00m\n\u001b[0;32m     40\u001b[0m     \u001b[38;5;66;03m# of NumPy unfortunately set up the import to replace (and hide) the\u001b[39;00m\n\u001b[0;32m     41\u001b[0m     \u001b[38;5;66;03m# error.  The traceback shouldn't be needed, but e.g. pytest plugins\u001b[39;00m\n\u001b[0;32m     42\u001b[0m     \u001b[38;5;66;03m# seem to swallow it and we should be failing anyway...\u001b[39;00m\n\u001b[0;32m     43\u001b[0m     sys\u001b[38;5;241m.\u001b[39mstderr\u001b[38;5;241m.\u001b[39mwrite(msg \u001b[38;5;241m+\u001b[39m tb_msg)\n\u001b[1;32m---> 44\u001b[0m     \u001b[38;5;28;01mraise\u001b[39;00m \u001b[38;5;167;01mImportError\u001b[39;00m(msg)\n\u001b[0;32m     46\u001b[0m ret \u001b[38;5;241m=\u001b[39m \u001b[38;5;28mgetattr\u001b[39m(_multiarray_umath, attr_name, \u001b[38;5;28;01mNone\u001b[39;00m)\n\u001b[0;32m     47\u001b[0m \u001b[38;5;28;01mif\u001b[39;00m ret \u001b[38;5;129;01mis\u001b[39;00m \u001b[38;5;28;01mNone\u001b[39;00m:\n",
      "\u001b[1;31mImportError\u001b[0m: \nA module that was compiled using NumPy 1.x cannot be run in\nNumPy 2.2.4 as it may crash. To support both 1.x and 2.x\nversions of NumPy, modules must be compiled with NumPy 2.0.\nSome module may need to rebuild instead e.g. with 'pybind11>=2.12'.\n\nIf you are a user of the module, the easiest solution will be to\ndowngrade to 'numpy<2' or try to upgrade the affected module.\nWe expect that some modules will need time to support NumPy 2.\n\n"
     ]
    },
    {
     "ename": "ImportError",
     "evalue": "initialization failed",
     "output_type": "error",
     "traceback": [
      "\u001b[1;31m---------------------------------------------------------------------------\u001b[0m",
      "\u001b[1;31mImportError\u001b[0m                               Traceback (most recent call last)",
      "\u001b[1;31mImportError\u001b[0m: numpy.core.multiarray failed to import",
      "\nThe above exception was the direct cause of the following exception:\n",
      "\u001b[1;31mImportError\u001b[0m                               Traceback (most recent call last)",
      "Cell \u001b[1;32mIn[1], line 3\u001b[0m\n\u001b[0;32m      1\u001b[0m \u001b[38;5;66;03m# Importing pandas and matplotlib\u001b[39;00m\n\u001b[0;32m      2\u001b[0m \u001b[38;5;28;01mimport\u001b[39;00m\u001b[38;5;250m \u001b[39m\u001b[38;5;21;01mpandas\u001b[39;00m\u001b[38;5;250m \u001b[39m\u001b[38;5;28;01mas\u001b[39;00m\u001b[38;5;250m \u001b[39m\u001b[38;5;21;01mpd\u001b[39;00m\n\u001b[1;32m----> 3\u001b[0m \u001b[38;5;28;01mimport\u001b[39;00m\u001b[38;5;250m \u001b[39m\u001b[38;5;21;01mmatplotlib\u001b[39;00m\u001b[38;5;21;01m.\u001b[39;00m\u001b[38;5;21;01mpyplot\u001b[39;00m\u001b[38;5;250m \u001b[39m\u001b[38;5;28;01mas\u001b[39;00m\u001b[38;5;250m \u001b[39m\u001b[38;5;21;01mplt\u001b[39;00m\n\u001b[0;32m      5\u001b[0m \u001b[38;5;66;03m# Read in the Netflix CSV as a DataFrame\u001b[39;00m\n\u001b[0;32m      6\u001b[0m netflix_df \u001b[38;5;241m=\u001b[39m pd\u001b[38;5;241m.\u001b[39mread_csv(\u001b[38;5;124m\"\u001b[39m\u001b[38;5;124mnetflix_data.csv\u001b[39m\u001b[38;5;124m\"\u001b[39m)\n",
      "File \u001b[1;32mc:\\Users\\Dell\\anaconda3\\Lib\\site-packages\\matplotlib\\__init__.py:159\u001b[0m\n\u001b[0;32m    155\u001b[0m \u001b[38;5;28;01mfrom\u001b[39;00m\u001b[38;5;250m \u001b[39m\u001b[38;5;21;01mpackaging\u001b[39;00m\u001b[38;5;21;01m.\u001b[39;00m\u001b[38;5;21;01mversion\u001b[39;00m\u001b[38;5;250m \u001b[39m\u001b[38;5;28;01mimport\u001b[39;00m parse \u001b[38;5;28;01mas\u001b[39;00m parse_version\n\u001b[0;32m    157\u001b[0m \u001b[38;5;66;03m# cbook must import matplotlib only within function\u001b[39;00m\n\u001b[0;32m    158\u001b[0m \u001b[38;5;66;03m# definitions, so it is safe to import from it here.\u001b[39;00m\n\u001b[1;32m--> 159\u001b[0m \u001b[38;5;28;01mfrom\u001b[39;00m\u001b[38;5;250m \u001b[39m\u001b[38;5;21;01m.\u001b[39;00m\u001b[38;5;250m \u001b[39m\u001b[38;5;28;01mimport\u001b[39;00m _api, _version, cbook, _docstring, rcsetup\n\u001b[0;32m    160\u001b[0m \u001b[38;5;28;01mfrom\u001b[39;00m\u001b[38;5;250m \u001b[39m\u001b[38;5;21;01mmatplotlib\u001b[39;00m\u001b[38;5;21;01m.\u001b[39;00m\u001b[38;5;21;01mcbook\u001b[39;00m\u001b[38;5;250m \u001b[39m\u001b[38;5;28;01mimport\u001b[39;00m sanitize_sequence\n\u001b[0;32m    161\u001b[0m \u001b[38;5;28;01mfrom\u001b[39;00m\u001b[38;5;250m \u001b[39m\u001b[38;5;21;01mmatplotlib\u001b[39;00m\u001b[38;5;21;01m.\u001b[39;00m\u001b[38;5;21;01m_api\u001b[39;00m\u001b[38;5;250m \u001b[39m\u001b[38;5;28;01mimport\u001b[39;00m MatplotlibDeprecationWarning\n",
      "File \u001b[1;32mc:\\Users\\Dell\\anaconda3\\Lib\\site-packages\\matplotlib\\rcsetup.py:28\u001b[0m\n\u001b[0;32m     26\u001b[0m \u001b[38;5;28;01mfrom\u001b[39;00m\u001b[38;5;250m \u001b[39m\u001b[38;5;21;01mmatplotlib\u001b[39;00m\u001b[38;5;21;01m.\u001b[39;00m\u001b[38;5;21;01mbackends\u001b[39;00m\u001b[38;5;250m \u001b[39m\u001b[38;5;28;01mimport\u001b[39;00m BackendFilter, backend_registry\n\u001b[0;32m     27\u001b[0m \u001b[38;5;28;01mfrom\u001b[39;00m\u001b[38;5;250m \u001b[39m\u001b[38;5;21;01mmatplotlib\u001b[39;00m\u001b[38;5;21;01m.\u001b[39;00m\u001b[38;5;21;01mcbook\u001b[39;00m\u001b[38;5;250m \u001b[39m\u001b[38;5;28;01mimport\u001b[39;00m ls_mapper\n\u001b[1;32m---> 28\u001b[0m \u001b[38;5;28;01mfrom\u001b[39;00m\u001b[38;5;250m \u001b[39m\u001b[38;5;21;01mmatplotlib\u001b[39;00m\u001b[38;5;21;01m.\u001b[39;00m\u001b[38;5;21;01mcolors\u001b[39;00m\u001b[38;5;250m \u001b[39m\u001b[38;5;28;01mimport\u001b[39;00m Colormap, is_color_like\n\u001b[0;32m     29\u001b[0m \u001b[38;5;28;01mfrom\u001b[39;00m\u001b[38;5;250m \u001b[39m\u001b[38;5;21;01mmatplotlib\u001b[39;00m\u001b[38;5;21;01m.\u001b[39;00m\u001b[38;5;21;01m_fontconfig_pattern\u001b[39;00m\u001b[38;5;250m \u001b[39m\u001b[38;5;28;01mimport\u001b[39;00m parse_fontconfig_pattern\n\u001b[0;32m     30\u001b[0m \u001b[38;5;28;01mfrom\u001b[39;00m\u001b[38;5;250m \u001b[39m\u001b[38;5;21;01mmatplotlib\u001b[39;00m\u001b[38;5;21;01m.\u001b[39;00m\u001b[38;5;21;01m_enums\u001b[39;00m\u001b[38;5;250m \u001b[39m\u001b[38;5;28;01mimport\u001b[39;00m JoinStyle, CapStyle\n",
      "File \u001b[1;32mc:\\Users\\Dell\\anaconda3\\Lib\\site-packages\\matplotlib\\colors.py:57\u001b[0m\n\u001b[0;32m     55\u001b[0m \u001b[38;5;28;01mimport\u001b[39;00m\u001b[38;5;250m \u001b[39m\u001b[38;5;21;01mmatplotlib\u001b[39;00m\u001b[38;5;250m \u001b[39m\u001b[38;5;28;01mas\u001b[39;00m\u001b[38;5;250m \u001b[39m\u001b[38;5;21;01mmpl\u001b[39;00m\n\u001b[0;32m     56\u001b[0m \u001b[38;5;28;01mimport\u001b[39;00m\u001b[38;5;250m \u001b[39m\u001b[38;5;21;01mnumpy\u001b[39;00m\u001b[38;5;250m \u001b[39m\u001b[38;5;28;01mas\u001b[39;00m\u001b[38;5;250m \u001b[39m\u001b[38;5;21;01mnp\u001b[39;00m\n\u001b[1;32m---> 57\u001b[0m \u001b[38;5;28;01mfrom\u001b[39;00m\u001b[38;5;250m \u001b[39m\u001b[38;5;21;01mmatplotlib\u001b[39;00m\u001b[38;5;250m \u001b[39m\u001b[38;5;28;01mimport\u001b[39;00m _api, _cm, cbook, scale\n\u001b[0;32m     58\u001b[0m \u001b[38;5;28;01mfrom\u001b[39;00m\u001b[38;5;250m \u001b[39m\u001b[38;5;21;01m.\u001b[39;00m\u001b[38;5;21;01m_color_data\u001b[39;00m\u001b[38;5;250m \u001b[39m\u001b[38;5;28;01mimport\u001b[39;00m BASE_COLORS, TABLEAU_COLORS, CSS4_COLORS, XKCD_COLORS\n\u001b[0;32m     61\u001b[0m \u001b[38;5;28;01mclass\u001b[39;00m\u001b[38;5;250m \u001b[39m\u001b[38;5;21;01m_ColorMapping\u001b[39;00m(\u001b[38;5;28mdict\u001b[39m):\n",
      "File \u001b[1;32mc:\\Users\\Dell\\anaconda3\\Lib\\site-packages\\matplotlib\\scale.py:22\u001b[0m\n\u001b[0;32m     20\u001b[0m \u001b[38;5;28;01mimport\u001b[39;00m\u001b[38;5;250m \u001b[39m\u001b[38;5;21;01mmatplotlib\u001b[39;00m\u001b[38;5;250m \u001b[39m\u001b[38;5;28;01mas\u001b[39;00m\u001b[38;5;250m \u001b[39m\u001b[38;5;21;01mmpl\u001b[39;00m\n\u001b[0;32m     21\u001b[0m \u001b[38;5;28;01mfrom\u001b[39;00m\u001b[38;5;250m \u001b[39m\u001b[38;5;21;01mmatplotlib\u001b[39;00m\u001b[38;5;250m \u001b[39m\u001b[38;5;28;01mimport\u001b[39;00m _api, _docstring\n\u001b[1;32m---> 22\u001b[0m \u001b[38;5;28;01mfrom\u001b[39;00m\u001b[38;5;250m \u001b[39m\u001b[38;5;21;01mmatplotlib\u001b[39;00m\u001b[38;5;21;01m.\u001b[39;00m\u001b[38;5;21;01mticker\u001b[39;00m\u001b[38;5;250m \u001b[39m\u001b[38;5;28;01mimport\u001b[39;00m (\n\u001b[0;32m     23\u001b[0m     NullFormatter, ScalarFormatter, LogFormatterSciNotation, LogitFormatter,\n\u001b[0;32m     24\u001b[0m     NullLocator, LogLocator, AutoLocator, AutoMinorLocator,\n\u001b[0;32m     25\u001b[0m     SymmetricalLogLocator, AsinhLocator, LogitLocator)\n\u001b[0;32m     26\u001b[0m \u001b[38;5;28;01mfrom\u001b[39;00m\u001b[38;5;250m \u001b[39m\u001b[38;5;21;01mmatplotlib\u001b[39;00m\u001b[38;5;21;01m.\u001b[39;00m\u001b[38;5;21;01mtransforms\u001b[39;00m\u001b[38;5;250m \u001b[39m\u001b[38;5;28;01mimport\u001b[39;00m Transform, IdentityTransform\n\u001b[0;32m     29\u001b[0m \u001b[38;5;28;01mclass\u001b[39;00m\u001b[38;5;250m \u001b[39m\u001b[38;5;21;01mScaleBase\u001b[39;00m:\n",
      "File \u001b[1;32mc:\\Users\\Dell\\anaconda3\\Lib\\site-packages\\matplotlib\\ticker.py:144\u001b[0m\n\u001b[0;32m    142\u001b[0m \u001b[38;5;28;01mimport\u001b[39;00m\u001b[38;5;250m \u001b[39m\u001b[38;5;21;01mmatplotlib\u001b[39;00m\u001b[38;5;250m \u001b[39m\u001b[38;5;28;01mas\u001b[39;00m\u001b[38;5;250m \u001b[39m\u001b[38;5;21;01mmpl\u001b[39;00m\n\u001b[0;32m    143\u001b[0m \u001b[38;5;28;01mfrom\u001b[39;00m\u001b[38;5;250m \u001b[39m\u001b[38;5;21;01mmatplotlib\u001b[39;00m\u001b[38;5;250m \u001b[39m\u001b[38;5;28;01mimport\u001b[39;00m _api, cbook\n\u001b[1;32m--> 144\u001b[0m \u001b[38;5;28;01mfrom\u001b[39;00m\u001b[38;5;250m \u001b[39m\u001b[38;5;21;01mmatplotlib\u001b[39;00m\u001b[38;5;250m \u001b[39m\u001b[38;5;28;01mimport\u001b[39;00m transforms \u001b[38;5;28;01mas\u001b[39;00m mtransforms\n\u001b[0;32m    146\u001b[0m _log \u001b[38;5;241m=\u001b[39m logging\u001b[38;5;241m.\u001b[39mgetLogger(\u001b[38;5;18m__name__\u001b[39m)\n\u001b[0;32m    148\u001b[0m __all__ \u001b[38;5;241m=\u001b[39m (\u001b[38;5;124m'\u001b[39m\u001b[38;5;124mTickHelper\u001b[39m\u001b[38;5;124m'\u001b[39m, \u001b[38;5;124m'\u001b[39m\u001b[38;5;124mFormatter\u001b[39m\u001b[38;5;124m'\u001b[39m, \u001b[38;5;124m'\u001b[39m\u001b[38;5;124mFixedFormatter\u001b[39m\u001b[38;5;124m'\u001b[39m,\n\u001b[0;32m    149\u001b[0m            \u001b[38;5;124m'\u001b[39m\u001b[38;5;124mNullFormatter\u001b[39m\u001b[38;5;124m'\u001b[39m, \u001b[38;5;124m'\u001b[39m\u001b[38;5;124mFuncFormatter\u001b[39m\u001b[38;5;124m'\u001b[39m, \u001b[38;5;124m'\u001b[39m\u001b[38;5;124mFormatStrFormatter\u001b[39m\u001b[38;5;124m'\u001b[39m,\n\u001b[0;32m    150\u001b[0m            \u001b[38;5;124m'\u001b[39m\u001b[38;5;124mStrMethodFormatter\u001b[39m\u001b[38;5;124m'\u001b[39m, \u001b[38;5;124m'\u001b[39m\u001b[38;5;124mScalarFormatter\u001b[39m\u001b[38;5;124m'\u001b[39m, \u001b[38;5;124m'\u001b[39m\u001b[38;5;124mLogFormatter\u001b[39m\u001b[38;5;124m'\u001b[39m,\n\u001b[1;32m   (...)\u001b[0m\n\u001b[0;32m    156\u001b[0m            \u001b[38;5;124m'\u001b[39m\u001b[38;5;124mMultipleLocator\u001b[39m\u001b[38;5;124m'\u001b[39m, \u001b[38;5;124m'\u001b[39m\u001b[38;5;124mMaxNLocator\u001b[39m\u001b[38;5;124m'\u001b[39m, \u001b[38;5;124m'\u001b[39m\u001b[38;5;124mAutoMinorLocator\u001b[39m\u001b[38;5;124m'\u001b[39m,\n\u001b[0;32m    157\u001b[0m            \u001b[38;5;124m'\u001b[39m\u001b[38;5;124mSymmetricalLogLocator\u001b[39m\u001b[38;5;124m'\u001b[39m, \u001b[38;5;124m'\u001b[39m\u001b[38;5;124mAsinhLocator\u001b[39m\u001b[38;5;124m'\u001b[39m, \u001b[38;5;124m'\u001b[39m\u001b[38;5;124mLogitLocator\u001b[39m\u001b[38;5;124m'\u001b[39m)\n",
      "File \u001b[1;32mc:\\Users\\Dell\\anaconda3\\Lib\\site-packages\\matplotlib\\transforms.py:49\u001b[0m\n\u001b[0;32m     46\u001b[0m \u001b[38;5;28;01mfrom\u001b[39;00m\u001b[38;5;250m \u001b[39m\u001b[38;5;21;01mnumpy\u001b[39;00m\u001b[38;5;21;01m.\u001b[39;00m\u001b[38;5;21;01mlinalg\u001b[39;00m\u001b[38;5;250m \u001b[39m\u001b[38;5;28;01mimport\u001b[39;00m inv\n\u001b[0;32m     48\u001b[0m \u001b[38;5;28;01mfrom\u001b[39;00m\u001b[38;5;250m \u001b[39m\u001b[38;5;21;01mmatplotlib\u001b[39;00m\u001b[38;5;250m \u001b[39m\u001b[38;5;28;01mimport\u001b[39;00m _api\n\u001b[1;32m---> 49\u001b[0m \u001b[38;5;28;01mfrom\u001b[39;00m\u001b[38;5;250m \u001b[39m\u001b[38;5;21;01mmatplotlib\u001b[39;00m\u001b[38;5;21;01m.\u001b[39;00m\u001b[38;5;21;01m_path\u001b[39;00m\u001b[38;5;250m \u001b[39m\u001b[38;5;28;01mimport\u001b[39;00m (\n\u001b[0;32m     50\u001b[0m     affine_transform, count_bboxes_overlapping_bbox, update_path_extents)\n\u001b[0;32m     51\u001b[0m \u001b[38;5;28;01mfrom\u001b[39;00m\u001b[38;5;250m \u001b[39m\u001b[38;5;21;01m.\u001b[39;00m\u001b[38;5;21;01mpath\u001b[39;00m\u001b[38;5;250m \u001b[39m\u001b[38;5;28;01mimport\u001b[39;00m Path\n\u001b[0;32m     53\u001b[0m DEBUG \u001b[38;5;241m=\u001b[39m \u001b[38;5;28;01mFalse\u001b[39;00m\n",
      "\u001b[1;31mImportError\u001b[0m: initialization failed"
     ]
    }
   ],
   "source": [
    "# Importing pandas and matplotlib\n",
    "import pandas as pd\n",
    "import matplotlib.pyplot as plt\n",
    "\n",
    "# Read in the Netflix CSV as a DataFrame\n",
    "netflix_df = pd.read_csv(\"netflix_data.csv\")\n",
    "\n",
    "# Start coding here!\n",
    "movies = netflix_df[(netflix_df[\"type\"]==\"Movie\") & (netflix_df[\"release_year\"]>=1990) & (netflix_df[\"release_year\"]<2000)]   #selects movies which released in 90s\n",
    "\n",
    "duration = int(movies[\"duration\"].mode()[0])  #Selects the first mode from mode list which is the most frequent duration\n",
    "\n",
    "short_action_movies = movies[(movies[\"duration\"] < 90) & (movies[\"genre\"].str.contains(\"Action\", case=False, na=False))]    #filters only short action movies\n",
    "plt.hist()\n",
    "\n",
    "short_movie_count = short_action_movies.shape[0]   #gives the number of rows there which is the movies\n",
    "\n",
    "print(short_movie_count)"
   ]
  }
 ],
 "metadata": {
  "kernelspec": {
   "display_name": "Python 3",
   "language": "python",
   "name": "python3"
  },
  "language_info": {
   "codemirror_mode": {
    "name": "ipython",
    "version": 3
   },
   "file_extension": ".py",
   "mimetype": "text/x-python",
   "name": "python",
   "nbconvert_exporter": "python",
   "pygments_lexer": "ipython3",
   "version": "3.12.6"
  }
 },
 "nbformat": 4,
 "nbformat_minor": 5
}
